2019-07-28 13:07:15 [ERROR   ] [flask_app.server.<module>:39        ] could not import GPIO
2019-07-28 13:47:04 [ERROR   ] [flask_app.server.main:153           ] loadEthMensa() takes 0 positional arguments but 3 were given
2019-07-28 13:47:04 [ERROR   ] [flask_app.server.main:154           ] Traceback (most recent call last):
  File "C:\Users\renez\OneDrive\Dokumente\zhmensa\backend\flask_app\server.py", line 147, in main
    loadEthMensa()
  File "C:\Users\renez\OneDrive\Dokumente\zhmensa\backend\flask_app\server.py", line 119, in loadEthMensa
    loadEthMensa("de", "2019-07-05", "lunch")
TypeError: loadEthMensa() takes 0 positional arguments but 3 were given

2019-07-28 14:00:07 [ERROR   ] [flask_app.server.main:164           ] __init__() takes 1 positional argument but 2 were given
2019-07-28 14:00:07 [ERROR   ] [flask_app.server.main:165           ] Traceback (most recent call last):
  File "C:\Users\renez\OneDrive\Dokumente\zhmensa\backend\flask_app\server.py", line 158, in main
    loadEthMensa()
  File "C:\Users\renez\OneDrive\Dokumente\zhmensa\backend\flask_app\server.py", line 124, in loadEthMensa
    loadEthMensaForParams("de", "2019-07-05", "lunch")
  File "C:\Users\renez\OneDrive\Dokumente\zhmensa\backend\flask_app\server.py", line 117, in loadEthMensaForParams
    curr_mensa = Mensa(mensa)
TypeError: __init__() takes 1 positional argument but 2 were given

2019-07-28 14:01:17 [ERROR   ] [flask_app.server.main:164           ] name 'addWeekday' is not defined
2019-07-28 14:01:17 [ERROR   ] [flask_app.server.main:165           ] Traceback (most recent call last):
  File "C:\Users\renez\OneDrive\Dokumente\zhmensa\backend\flask_app\server.py", line 158, in main
    loadEthMensa()
  File "C:\Users\renez\OneDrive\Dokumente\zhmensa\backend\flask_app\server.py", line 124, in loadEthMensa
    loadEthMensaForParams("de", "2019-07-05", "lunch")
  File "C:\Users\renez\OneDrive\Dokumente\zhmensa\backend\flask_app\server.py", line 119, in loadEthMensaForParams
    curr_mensa-addWeekday()
NameError: name 'addWeekday' is not defined

2019-07-28 14:01:34 [ERROR   ] [flask_app.server.main:164           ] name 'addWeekday' is not defined
2019-07-28 14:01:34 [ERROR   ] [flask_app.server.main:165           ] Traceback (most recent call last):
  File "C:\Users\renez\OneDrive\Dokumente\zhmensa\backend\flask_app\server.py", line 158, in main
    loadEthMensa()
  File "C:\Users\renez\OneDrive\Dokumente\zhmensa\backend\flask_app\server.py", line 124, in loadEthMensa
    loadEthMensaForParams("de", "2019-07-05", "lunch")
  File "C:\Users\renez\OneDrive\Dokumente\zhmensa\backend\flask_app\server.py", line 119, in loadEthMensaForParams
    curr_mensa-addWeekday()
NameError: name 'addWeekday' is not defined

2019-07-28 14:01:49 [ERROR   ] [flask_app.server.main:164           ] addWeekday() missing 1 required positional argument: 'weekday'
2019-07-28 14:01:49 [ERROR   ] [flask_app.server.main:165           ] Traceback (most recent call last):
  File "C:\Users\renez\OneDrive\Dokumente\zhmensa\backend\flask_app\server.py", line 158, in main
    loadEthMensa()
  File "C:\Users\renez\OneDrive\Dokumente\zhmensa\backend\flask_app\server.py", line 124, in loadEthMensa
    loadEthMensaForParams("de", "2019-07-05", "lunch")
  File "C:\Users\renez\OneDrive\Dokumente\zhmensa\backend\flask_app\server.py", line 119, in loadEthMensaForParams
    curr_mensa.addWeekday()
TypeError: addWeekday() missing 1 required positional argument: 'weekday'

2019-07-28 14:39:13 [ERROR   ] [flask_app.server.main:165           ] HTTPSConnectionPool(host='www.webservices.ethz.ch', port=443): Max retries exceeded with url: /gastro/v1/RVRI/Q1E1/meals/de/2019-07-05/lunch (Caused by NewConnectionError('<urllib3.connection.VerifiedHTTPSConnection object at 0x000001DB4F1BA0F0>: Failed to establish a new connection: [Errno 11001] getaddrinfo failed'))
2019-07-28 14:39:13 [ERROR   ] [flask_app.server.main:166           ] Traceback (most recent call last):
  File "C:\Users\renez\AppData\Local\Programs\Python\Python37\lib\site-packages\urllib3\connection.py", line 159, in _new_conn
    (self._dns_host, self.port), self.timeout, **extra_kw)
  File "C:\Users\renez\AppData\Local\Programs\Python\Python37\lib\site-packages\urllib3\util\connection.py", line 57, in create_connection
    for res in socket.getaddrinfo(host, port, family, socket.SOCK_STREAM):
  File "C:\Users\renez\AppData\Local\Programs\Python\Python37\lib\socket.py", line 748, in getaddrinfo
    for res in _socket.getaddrinfo(host, port, family, type, proto, flags):
socket.gaierror: [Errno 11001] getaddrinfo failed

During handling of the above exception, another exception occurred:

Traceback (most recent call last):
  File "C:\Users\renez\AppData\Local\Programs\Python\Python37\lib\site-packages\urllib3\connectionpool.py", line 600, in urlopen
    chunked=chunked)
  File "C:\Users\renez\AppData\Local\Programs\Python\Python37\lib\site-packages\urllib3\connectionpool.py", line 343, in _make_request
    self._validate_conn(conn)
  File "C:\Users\renez\AppData\Local\Programs\Python\Python37\lib\site-packages\urllib3\connectionpool.py", line 839, in _validate_conn
    conn.connect()
  File "C:\Users\renez\AppData\Local\Programs\Python\Python37\lib\site-packages\urllib3\connection.py", line 301, in connect
    conn = self._new_conn()
  File "C:\Users\renez\AppData\Local\Programs\Python\Python37\lib\site-packages\urllib3\connection.py", line 168, in _new_conn
    self, "Failed to establish a new connection: %s" % e)
urllib3.exceptions.NewConnectionError: <urllib3.connection.VerifiedHTTPSConnection object at 0x000001DB4F1BA0F0>: Failed to establish a new connection: [Errno 11001] getaddrinfo failed

During handling of the above exception, another exception occurred:

Traceback (most recent call last):
  File "C:\Users\renez\AppData\Local\Programs\Python\Python37\lib\site-packages\requests\adapters.py", line 449, in send
    timeout=timeout
  File "C:\Users\renez\AppData\Local\Programs\Python\Python37\lib\site-packages\urllib3\connectionpool.py", line 638, in urlopen
    _stacktrace=sys.exc_info()[2])
  File "C:\Users\renez\AppData\Local\Programs\Python\Python37\lib\site-packages\urllib3\util\retry.py", line 398, in increment
    raise MaxRetryError(_pool, url, error or ResponseError(cause))
urllib3.exceptions.MaxRetryError: HTTPSConnectionPool(host='www.webservices.ethz.ch', port=443): Max retries exceeded with url: /gastro/v1/RVRI/Q1E1/meals/de/2019-07-05/lunch (Caused by NewConnectionError('<urllib3.connection.VerifiedHTTPSConnection object at 0x000001DB4F1BA0F0>: Failed to establish a new connection: [Errno 11001] getaddrinfo failed'))

During handling of the above exception, another exception occurred:

Traceback (most recent call last):
  File "C:\Users\renez\OneDrive\Dokumente\zhmensa\backend\flask_app\server.py", line 159, in main
    loadEthMensa()
  File "C:\Users\renez\OneDrive\Dokumente\zhmensa\backend\flask_app\server.py", line 125, in loadEthMensa
    loadEthMensaForParams("de", "2019-07-05", "lunch")
  File "C:\Users\renez\OneDrive\Dokumente\zhmensa\backend\flask_app\server.py", line 114, in loadEthMensaForParams
    r = requests.get(url = URL)
  File "C:\Users\renez\AppData\Local\Programs\Python\Python37\lib\site-packages\requests\api.py", line 75, in get
    return request('get', url, params=params, **kwargs)
  File "C:\Users\renez\AppData\Local\Programs\Python\Python37\lib\site-packages\requests\api.py", line 60, in request
    return session.request(method=method, url=url, **kwargs)
  File "C:\Users\renez\AppData\Local\Programs\Python\Python37\lib\site-packages\requests\sessions.py", line 533, in request
    resp = self.send(prep, **send_kwargs)
  File "C:\Users\renez\AppData\Local\Programs\Python\Python37\lib\site-packages\requests\sessions.py", line 646, in send
    r = adapter.send(request, **kwargs)
  File "C:\Users\renez\AppData\Local\Programs\Python\Python37\lib\site-packages\requests\adapters.py", line 516, in send
    raise ConnectionError(e, request=request)
requests.exceptions.ConnectionError: HTTPSConnectionPool(host='www.webservices.ethz.ch', port=443): Max retries exceeded with url: /gastro/v1/RVRI/Q1E1/meals/de/2019-07-05/lunch (Caused by NewConnectionError('<urllib3.connection.VerifiedHTTPSConnection object at 0x000001DB4F1BA0F0>: Failed to establish a new connection: [Errno 11001] getaddrinfo failed'))

2019-07-28 14:39:38 [ERROR   ] [flask_app.server.main:165           ] 'Menu' object has no attribute 'convertPricesToStr'
2019-07-28 14:39:38 [ERROR   ] [flask_app.server.main:166           ] Traceback (most recent call last):
  File "C:\Users\renez\OneDrive\Dokumente\zhmensa\backend\flask_app\server.py", line 159, in main
    loadEthMensa()
  File "C:\Users\renez\OneDrive\Dokumente\zhmensa\backend\flask_app\server.py", line 125, in loadEthMensa
    loadEthMensaForParams("de", "2019-07-05", "lunch")
  File "C:\Users\renez\OneDrive\Dokumente\zhmensa\backend\flask_app\server.py", line 119, in loadEthMensaForParams
    type = MealType(mensa, type)
  File "C:\Users\renez\OneDrive\Dokumente\zhmensa\backend\flask_app\server.py", line 190, in __init__
    self.menus.append(Menu(menu, jsonObject["mensa"]))
  File "C:\Users\renez\OneDrive\Dokumente\zhmensa\backend\flask_app\server.py", line 197, in __init__
    self.prices = self.convertPricesToStr( meal["prices"])
AttributeError: 'Menu' object has no attribute 'convertPricesToStr'

2019-07-28 14:41:03 [ERROR   ] [flask_app.server.main:165           ] Object of type Mensa is not JSON serializable
2019-07-28 14:41:04 [ERROR   ] [flask_app.server.main:166           ] Traceback (most recent call last):
  File "C:\Users\renez\OneDrive\Dokumente\zhmensa\backend\flask_app\server.py", line 159, in main
    loadEthMensa()
  File "C:\Users\renez\OneDrive\Dokumente\zhmensa\backend\flask_app\server.py", line 125, in loadEthMensa
    loadEthMensaForParams("de", "2019-07-05", "lunch")
  File "C:\Users\renez\OneDrive\Dokumente\zhmensa\backend\flask_app\server.py", line 121, in loadEthMensaForParams
    print(json.dumps(curr_mensa, indent=2, sort_keys=False))
  File "C:\Users\renez\AppData\Local\Programs\Python\Python37\lib\json\__init__.py", line 238, in dumps
    **kw).encode(obj)
  File "C:\Users\renez\AppData\Local\Programs\Python\Python37\lib\json\encoder.py", line 201, in encode
    chunks = list(chunks)
  File "C:\Users\renez\AppData\Local\Programs\Python\Python37\lib\json\encoder.py", line 438, in _iterencode
    o = _default(o)
  File "C:\Users\renez\AppData\Local\Programs\Python\Python37\lib\json\encoder.py", line 179, in default
    raise TypeError(f'Object of type {o.__class__.__name__} '
TypeError: Object of type Mensa is not JSON serializable

2019-07-28 15:21:06 [ERROR   ] [flask_app.server.main:166           ] Object of type ETHWeekday is not JSON serializable
2019-07-28 15:21:06 [ERROR   ] [flask_app.server.main:167           ] Traceback (most recent call last):
  File "C:\Users\renez\OneDrive\Dokumente\zhmensa\backend\flask_app\server.py", line 160, in main
    loadEthMensa()
  File "C:\Users\renez\OneDrive\Dokumente\zhmensa\backend\flask_app\server.py", line 126, in loadEthMensa
    loadEthMensaForParams("de", "2019-07-05", "lunch")
  File "C:\Users\renez\OneDrive\Dokumente\zhmensa\backend\flask_app\server.py", line 122, in loadEthMensaForParams
    print(json.dumps(curr_mensa.__dict__, indent=2, sort_keys=False))
  File "C:\Users\renez\AppData\Local\Programs\Python\Python37\lib\json\__init__.py", line 238, in dumps
    **kw).encode(obj)
  File "C:\Users\renez\AppData\Local\Programs\Python\Python37\lib\json\encoder.py", line 201, in encode
    chunks = list(chunks)
  File "C:\Users\renez\AppData\Local\Programs\Python\Python37\lib\json\encoder.py", line 431, in _iterencode
    yield from _iterencode_dict(o, _current_indent_level)
  File "C:\Users\renez\AppData\Local\Programs\Python\Python37\lib\json\encoder.py", line 405, in _iterencode_dict
    yield from chunks
  File "C:\Users\renez\AppData\Local\Programs\Python\Python37\lib\json\encoder.py", line 325, in _iterencode_list
    yield from chunks
  File "C:\Users\renez\AppData\Local\Programs\Python\Python37\lib\json\encoder.py", line 438, in _iterencode
    o = _default(o)
  File "C:\Users\renez\AppData\Local\Programs\Python\Python37\lib\json\encoder.py", line 179, in default
    raise TypeError(f'Object of type {o.__class__.__name__} '
TypeError: Object of type ETHWeekday is not JSON serializable

2019-07-28 15:23:32 [ERROR   ] [flask_app.server.main:167           ] name 'team' is not defined
2019-07-28 15:23:32 [ERROR   ] [flask_app.server.main:168           ] Traceback (most recent call last):
  File "C:\Users\renez\OneDrive\Dokumente\zhmensa\backend\flask_app\server.py", line 161, in main
    loadEthMensa()
  File "C:\Users\renez\OneDrive\Dokumente\zhmensa\backend\flask_app\server.py", line 127, in loadEthMensa
    loadEthMensaForParams("de", "2019-07-05", "lunch")
  File "C:\Users\renez\OneDrive\Dokumente\zhmensa\backend\flask_app\server.py", line 122, in loadEthMensaForParams
    json_data = json.dumps(team.__dict__, lambda o: o.__dict__, indent=4, sort_keys=False)
NameError: name 'team' is not defined

2019-07-28 15:23:41 [ERROR   ] [flask_app.server.main:167           ] dumps() takes 1 positional argument but 2 positional arguments (and 2 keyword-only arguments) were given
2019-07-28 15:23:41 [ERROR   ] [flask_app.server.main:168           ] Traceback (most recent call last):
  File "C:\Users\renez\OneDrive\Dokumente\zhmensa\backend\flask_app\server.py", line 161, in main
    loadEthMensa()
  File "C:\Users\renez\OneDrive\Dokumente\zhmensa\backend\flask_app\server.py", line 127, in loadEthMensa
    loadEthMensaForParams("de", "2019-07-05", "lunch")
  File "C:\Users\renez\OneDrive\Dokumente\zhmensa\backend\flask_app\server.py", line 122, in loadEthMensaForParams
    json_data = json.dumps(curr_mensa.__dict__, lambda o: o.__dict__, indent=4, sort_keys=False)
TypeError: dumps() takes 1 positional argument but 2 positional arguments (and 2 keyword-only arguments) were given

2019-07-28 15:24:46 [ERROR   ] [flask_app.server.main:167           ] name 'team' is not defined
2019-07-28 15:24:46 [ERROR   ] [flask_app.server.main:168           ] Traceback (most recent call last):
  File "C:\Users\renez\OneDrive\Dokumente\zhmensa\backend\flask_app\server.py", line 161, in main
    loadEthMensa()
  File "C:\Users\renez\OneDrive\Dokumente\zhmensa\backend\flask_app\server.py", line 127, in loadEthMensa
    loadEthMensaForParams("de", "2019-07-05", "lunch")
  File "C:\Users\renez\OneDrive\Dokumente\zhmensa\backend\flask_app\server.py", line 122, in loadEthMensaForParams
    json_data = json.dumps(team.__dict__, lambda o: o.__dict__, indent=4)
NameError: name 'team' is not defined

2019-07-28 15:24:57 [ERROR   ] [flask_app.server.main:167           ] dumps() takes 1 positional argument but 2 positional arguments (and 1 keyword-only argument) were given
2019-07-28 15:24:57 [ERROR   ] [flask_app.server.main:168           ] Traceback (most recent call last):
  File "C:\Users\renez\OneDrive\Dokumente\zhmensa\backend\flask_app\server.py", line 161, in main
    loadEthMensa()
  File "C:\Users\renez\OneDrive\Dokumente\zhmensa\backend\flask_app\server.py", line 127, in loadEthMensa
    loadEthMensaForParams("de", "2019-07-05", "lunch")
  File "C:\Users\renez\OneDrive\Dokumente\zhmensa\backend\flask_app\server.py", line 122, in loadEthMensaForParams
    json_data = json.dumps(curr_mensa.__dict__, lambda o: o.__dict__, indent=4)
TypeError: dumps() takes 1 positional argument but 2 positional arguments (and 1 keyword-only argument) were given

2019-07-28 15:29:31 [ERROR   ] [flask_app.server.main:183           ] name 'Employee' is not defined
2019-07-28 15:29:32 [ERROR   ] [flask_app.server.main:184           ] Traceback (most recent call last):
  File "C:\Users\renez\OneDrive\Dokumente\zhmensa\backend\flask_app\server.py", line 177, in main
    loadEthMensa()
  File "C:\Users\renez\OneDrive\Dokumente\zhmensa\backend\flask_app\server.py", line 143, in loadEthMensa
    loadEthMensaForParams("de", "2019-07-05", "lunch")
  File "C:\Users\renez\OneDrive\Dokumente\zhmensa\backend\flask_app\server.py", line 135, in loadEthMensaForParams
    json_data = json.dumps(curr_mensa, cls=CustomJsonEncoder)
  File "C:\Users\renez\AppData\Local\Programs\Python\Python37\lib\json\__init__.py", line 238, in dumps
    **kw).encode(obj)
  File "C:\Users\renez\AppData\Local\Programs\Python\Python37\lib\json\encoder.py", line 199, in encode
    chunks = self.iterencode(o, _one_shot=True)
  File "C:\Users\renez\AppData\Local\Programs\Python\Python37\lib\json\encoder.py", line 257, in iterencode
    return _iterencode(o, 0)
  File "C:\Users\renez\OneDrive\Dokumente\zhmensa\backend\flask_app\server.py", line 129, in default
    if isinstance(o, (Employee, Autocar)):
NameError: name 'Employee' is not defined

2019-07-28 15:48:03 [ERROR   ] [flask_app.server.main:193           ] argument of type 'builtin_function_or_method' is not iterable
2019-07-28 15:48:03 [ERROR   ] [flask_app.server.main:194           ] Traceback (most recent call last):
  File "C:\Users\renez\OneDrive\Dokumente\zhmensa\backend\flask_app\server.py", line 187, in main
    loadEthMensa()
  File "C:\Users\renez\OneDrive\Dokumente\zhmensa\backend\flask_app\server.py", line 153, in loadEthMensa
    loadEthMensaForParams("de", "2019-07-05", "lunch")
  File "C:\Users\renez\OneDrive\Dokumente\zhmensa\backend\flask_app\server.py", line 120, in loadEthMensaForParams
    if(not mensa in mensaMapping.keys):
TypeError: argument of type 'builtin_function_or_method' is not iterable

2019-07-28 15:51:07 [ERROR   ] [flask_app.server.main:193           ] unhashable type: 'dict'
2019-07-28 15:51:07 [ERROR   ] [flask_app.server.main:194           ] Traceback (most recent call last):
  File "C:\Users\renez\OneDrive\Dokumente\zhmensa\backend\flask_app\server.py", line 187, in main
    loadEthMensa()
  File "C:\Users\renez\OneDrive\Dokumente\zhmensa\backend\flask_app\server.py", line 153, in loadEthMensa
    loadEthMensaForParams("de", "2019-07-05", "lunch")
  File "C:\Users\renez\OneDrive\Dokumente\zhmensa\backend\flask_app\server.py", line 120, in loadEthMensaForParams
    if(not mensa in mensaMapping.keys()):
TypeError: unhashable type: 'dict'

2019-07-28 15:51:36 [ERROR   ] [flask_app.server.main:193           ] unhashable type: 'dict'
2019-07-28 15:51:36 [ERROR   ] [flask_app.server.main:194           ] Traceback (most recent call last):
  File "C:\Users\renez\OneDrive\Dokumente\zhmensa\backend\flask_app\server.py", line 187, in main
    loadEthMensa()
  File "C:\Users\renez\OneDrive\Dokumente\zhmensa\backend\flask_app\server.py", line 153, in loadEthMensa
    loadEthMensaForParams("de", "2019-07-05", "lunch")
  File "C:\Users\renez\OneDrive\Dokumente\zhmensa\backend\flask_app\server.py", line 120, in loadEthMensaForParams
    if(not mensa in mensaMapping):
TypeError: unhashable type: 'dict'

2019-07-28 15:51:39 [ERROR   ] [flask_app.server.main:193           ] unhashable type: 'dict'
2019-07-28 15:51:39 [ERROR   ] [flask_app.server.main:194           ] Traceback (most recent call last):
  File "C:\Users\renez\OneDrive\Dokumente\zhmensa\backend\flask_app\server.py", line 187, in main
    loadEthMensa()
  File "C:\Users\renez\OneDrive\Dokumente\zhmensa\backend\flask_app\server.py", line 153, in loadEthMensa
    loadEthMensaForParams("de", "2019-07-05", "lunch")
  File "C:\Users\renez\OneDrive\Dokumente\zhmensa\backend\flask_app\server.py", line 120, in loadEthMensaForParams
    if(not mensa in mensaMapping):
TypeError: unhashable type: 'dict'

2019-07-28 16:10:17 [ERROR   ] [flask_app.server.main:190           ] HTTPSConnectionPool(host='www.webservices.ethz.ch', port=443): Max retries exceeded with url: /gastro/v1/RVRI/Q1E1/meals/de/2019-07-05/lunch (Caused by NewConnectionError('<urllib3.connection.VerifiedHTTPSConnection object at 0x000002966221D240>: Failed to establish a new connection: [Errno 11001] getaddrinfo failed'))
2019-07-28 16:10:17 [ERROR   ] [flask_app.server.main:191           ] Traceback (most recent call last):
  File "C:\Users\renez\AppData\Local\Programs\Python\Python37\lib\site-packages\urllib3\connection.py", line 159, in _new_conn
    (self._dns_host, self.port), self.timeout, **extra_kw)
  File "C:\Users\renez\AppData\Local\Programs\Python\Python37\lib\site-packages\urllib3\util\connection.py", line 57, in create_connection
    for res in socket.getaddrinfo(host, port, family, socket.SOCK_STREAM):
  File "C:\Users\renez\AppData\Local\Programs\Python\Python37\lib\socket.py", line 748, in getaddrinfo
    for res in _socket.getaddrinfo(host, port, family, type, proto, flags):
socket.gaierror: [Errno 11001] getaddrinfo failed

During handling of the above exception, another exception occurred:

Traceback (most recent call last):
  File "C:\Users\renez\AppData\Local\Programs\Python\Python37\lib\site-packages\urllib3\connectionpool.py", line 600, in urlopen
    chunked=chunked)
  File "C:\Users\renez\AppData\Local\Programs\Python\Python37\lib\site-packages\urllib3\connectionpool.py", line 343, in _make_request
    self._validate_conn(conn)
  File "C:\Users\renez\AppData\Local\Programs\Python\Python37\lib\site-packages\urllib3\connectionpool.py", line 839, in _validate_conn
    conn.connect()
  File "C:\Users\renez\AppData\Local\Programs\Python\Python37\lib\site-packages\urllib3\connection.py", line 301, in connect
    conn = self._new_conn()
  File "C:\Users\renez\AppData\Local\Programs\Python\Python37\lib\site-packages\urllib3\connection.py", line 168, in _new_conn
    self, "Failed to establish a new connection: %s" % e)
urllib3.exceptions.NewConnectionError: <urllib3.connection.VerifiedHTTPSConnection object at 0x000002966221D240>: Failed to establish a new connection: [Errno 11001] getaddrinfo failed

During handling of the above exception, another exception occurred:

Traceback (most recent call last):
  File "C:\Users\renez\AppData\Local\Programs\Python\Python37\lib\site-packages\requests\adapters.py", line 449, in send
    timeout=timeout
  File "C:\Users\renez\AppData\Local\Programs\Python\Python37\lib\site-packages\urllib3\connectionpool.py", line 638, in urlopen
    _stacktrace=sys.exc_info()[2])
  File "C:\Users\renez\AppData\Local\Programs\Python\Python37\lib\site-packages\urllib3\util\retry.py", line 398, in increment
    raise MaxRetryError(_pool, url, error or ResponseError(cause))
urllib3.exceptions.MaxRetryError: HTTPSConnectionPool(host='www.webservices.ethz.ch', port=443): Max retries exceeded with url: /gastro/v1/RVRI/Q1E1/meals/de/2019-07-05/lunch (Caused by NewConnectionError('<urllib3.connection.VerifiedHTTPSConnection object at 0x000002966221D240>: Failed to establish a new connection: [Errno 11001] getaddrinfo failed'))

During handling of the above exception, another exception occurred:

Traceback (most recent call last):
  File "C:\Users\renez\OneDrive\Dokumente\zhmensa\backend\flask_app\server.py", line 184, in main
    loadEthMensa()
  File "C:\Users\renez\OneDrive\Dokumente\zhmensa\backend\flask_app\server.py", line 153, in loadEthMensa
    loadEthMensaForParams("de", "2019-07-05", "lunch")
  File "C:\Users\renez\OneDrive\Dokumente\zhmensa\backend\flask_app\server.py", line 115, in loadEthMensaForParams
    r = requests.get(url = URL)
  File "C:\Users\renez\AppData\Local\Programs\Python\Python37\lib\site-packages\requests\api.py", line 75, in get
    return request('get', url, params=params, **kwargs)
  File "C:\Users\renez\AppData\Local\Programs\Python\Python37\lib\site-packages\requests\api.py", line 60, in request
    return session.request(method=method, url=url, **kwargs)
  File "C:\Users\renez\AppData\Local\Programs\Python\Python37\lib\site-packages\requests\sessions.py", line 533, in request
    resp = self.send(prep, **send_kwargs)
  File "C:\Users\renez\AppData\Local\Programs\Python\Python37\lib\site-packages\requests\sessions.py", line 646, in send
    r = adapter.send(request, **kwargs)
  File "C:\Users\renez\AppData\Local\Programs\Python\Python37\lib\site-packages\requests\adapters.py", line 516, in send
    raise ConnectionError(e, request=request)
requests.exceptions.ConnectionError: HTTPSConnectionPool(host='www.webservices.ethz.ch', port=443): Max retries exceeded with url: /gastro/v1/RVRI/Q1E1/meals/de/2019-07-05/lunch (Caused by NewConnectionError('<urllib3.connection.VerifiedHTTPSConnection object at 0x000002966221D240>: Failed to establish a new connection: [Errno 11001] getaddrinfo failed'))

2019-07-28 16:10:48 [ERROR   ] [flask_app.server.main:190           ] HTTPSConnectionPool(host='www.webservices.ethz.ch', port=443): Max retries exceeded with url: /gastro/v1/RVRI/Q1E1/meals/de/2019-07-05/lunch (Caused by NewConnectionError('<urllib3.connection.VerifiedHTTPSConnection object at 0x000001D40085D470>: Failed to establish a new connection: [Errno 11001] getaddrinfo failed'))
2019-07-28 16:10:48 [ERROR   ] [flask_app.server.main:191           ] Traceback (most recent call last):
  File "C:\Users\renez\AppData\Local\Programs\Python\Python37\lib\site-packages\urllib3\connection.py", line 159, in _new_conn
    (self._dns_host, self.port), self.timeout, **extra_kw)
  File "C:\Users\renez\AppData\Local\Programs\Python\Python37\lib\site-packages\urllib3\util\connection.py", line 57, in create_connection
    for res in socket.getaddrinfo(host, port, family, socket.SOCK_STREAM):
  File "C:\Users\renez\AppData\Local\Programs\Python\Python37\lib\socket.py", line 748, in getaddrinfo
    for res in _socket.getaddrinfo(host, port, family, type, proto, flags):
socket.gaierror: [Errno 11001] getaddrinfo failed

During handling of the above exception, another exception occurred:

Traceback (most recent call last):
  File "C:\Users\renez\AppData\Local\Programs\Python\Python37\lib\site-packages\urllib3\connectionpool.py", line 600, in urlopen
    chunked=chunked)
  File "C:\Users\renez\AppData\Local\Programs\Python\Python37\lib\site-packages\urllib3\connectionpool.py", line 343, in _make_request
    self._validate_conn(conn)
  File "C:\Users\renez\AppData\Local\Programs\Python\Python37\lib\site-packages\urllib3\connectionpool.py", line 839, in _validate_conn
    conn.connect()
  File "C:\Users\renez\AppData\Local\Programs\Python\Python37\lib\site-packages\urllib3\connection.py", line 301, in connect
    conn = self._new_conn()
  File "C:\Users\renez\AppData\Local\Programs\Python\Python37\lib\site-packages\urllib3\connection.py", line 168, in _new_conn
    self, "Failed to establish a new connection: %s" % e)
urllib3.exceptions.NewConnectionError: <urllib3.connection.VerifiedHTTPSConnection object at 0x000001D40085D470>: Failed to establish a new connection: [Errno 11001] getaddrinfo failed

During handling of the above exception, another exception occurred:

Traceback (most recent call last):
  File "C:\Users\renez\AppData\Local\Programs\Python\Python37\lib\site-packages\requests\adapters.py", line 449, in send
    timeout=timeout
  File "C:\Users\renez\AppData\Local\Programs\Python\Python37\lib\site-packages\urllib3\connectionpool.py", line 638, in urlopen
    _stacktrace=sys.exc_info()[2])
  File "C:\Users\renez\AppData\Local\Programs\Python\Python37\lib\site-packages\urllib3\util\retry.py", line 398, in increment
    raise MaxRetryError(_pool, url, error or ResponseError(cause))
urllib3.exceptions.MaxRetryError: HTTPSConnectionPool(host='www.webservices.ethz.ch', port=443): Max retries exceeded with url: /gastro/v1/RVRI/Q1E1/meals/de/2019-07-05/lunch (Caused by NewConnectionError('<urllib3.connection.VerifiedHTTPSConnection object at 0x000001D40085D470>: Failed to establish a new connection: [Errno 11001] getaddrinfo failed'))

During handling of the above exception, another exception occurred:

Traceback (most recent call last):
  File "C:\Users\renez\OneDrive\Dokumente\zhmensa\backend\flask_app\server.py", line 184, in main
    loadEthMensa()
  File "C:\Users\renez\OneDrive\Dokumente\zhmensa\backend\flask_app\server.py", line 153, in loadEthMensa
    loadEthMensaForParams("de", "2019-07-05", "lunch")
  File "C:\Users\renez\OneDrive\Dokumente\zhmensa\backend\flask_app\server.py", line 115, in loadEthMensaForParams
    r = requests.get(url = URL)
  File "C:\Users\renez\AppData\Local\Programs\Python\Python37\lib\site-packages\requests\api.py", line 75, in get
    return request('get', url, params=params, **kwargs)
  File "C:\Users\renez\AppData\Local\Programs\Python\Python37\lib\site-packages\requests\api.py", line 60, in request
    return session.request(method=method, url=url, **kwargs)
  File "C:\Users\renez\AppData\Local\Programs\Python\Python37\lib\site-packages\requests\sessions.py", line 533, in request
    resp = self.send(prep, **send_kwargs)
  File "C:\Users\renez\AppData\Local\Programs\Python\Python37\lib\site-packages\requests\sessions.py", line 646, in send
    r = adapter.send(request, **kwargs)
  File "C:\Users\renez\AppData\Local\Programs\Python\Python37\lib\site-packages\requests\adapters.py", line 516, in send
    raise ConnectionError(e, request=request)
requests.exceptions.ConnectionError: HTTPSConnectionPool(host='www.webservices.ethz.ch', port=443): Max retries exceeded with url: /gastro/v1/RVRI/Q1E1/meals/de/2019-07-05/lunch (Caused by NewConnectionError('<urllib3.connection.VerifiedHTTPSConnection object at 0x000001D40085D470>: Failed to establish a new connection: [Errno 11001] getaddrinfo failed'))

2019-07-28 19:42:28 [ERROR   ] [flask_app.server.main:199           ] can only concatenate str (not "datetime.date") to str
2019-07-28 19:42:28 [ERROR   ] [flask_app.server.main:200           ] Traceback (most recent call last):
  File "C:\Users\renez\OneDrive\Dokumente\zhmensa\backend\flask_app\server.py", line 193, in main
    loadEthMensa(startOfWeek)
  File "C:\Users\renez\OneDrive\Dokumente\zhmensa\backend\flask_app\server.py", line 158, in loadEthMensa
    loadEthMensaForParams("de", startOfWeek + timedelta(days = i), "lunch")
  File "C:\Users\renez\OneDrive\Dokumente\zhmensa\backend\flask_app\server.py", line 124, in loadEthMensaForParams
    URL = "https://www.webservices.ethz.ch/gastro/v1/RVRI/Q1E1/meals/" + lang + "/" +day + "/" + type;
TypeError: can only concatenate str (not "datetime.date") to str

2019-07-28 21:40:02 [ERROR   ] [flask_app.server.main:207           ] 'Mensa' object has no attribute 'category'
2019-07-28 21:40:02 [ERROR   ] [flask_app.server.main:208           ] Traceback (most recent call last):
  File "C:\Users\renez\OneDrive\Dokumente\zhmensa\backend\flask_app\server.py", line 201, in main
    loadEthMensa(startOfWeek)
  File "C:\Users\renez\OneDrive\Dokumente\zhmensa\backend\flask_app\server.py", line 166, in loadEthMensa
    loadEthMensaForParams("de", str(startOfWeek + timedelta(days = i)), "lunch", i)
  File "C:\Users\renez\OneDrive\Dokumente\zhmensa\backend\flask_app\server.py", line 150, in loadEthMensaForParams
    curr_mensa.category("ETH-Zentrum")
AttributeError: 'Mensa' object has no attribute 'category'

2019-07-28 21:40:26 [ERROR   ] [flask_app.server.main:207           ] 'str' object is not callable
2019-07-28 21:40:26 [ERROR   ] [flask_app.server.main:208           ] Traceback (most recent call last):
  File "C:\Users\renez\OneDrive\Dokumente\zhmensa\backend\flask_app\server.py", line 201, in main
    loadEthMensa(startOfWeek)
  File "C:\Users\renez\OneDrive\Dokumente\zhmensa\backend\flask_app\server.py", line 166, in loadEthMensa
    loadEthMensaForParams("de", str(startOfWeek + timedelta(days = i)), "lunch", i)
  File "C:\Users\renez\OneDrive\Dokumente\zhmensa\backend\flask_app\server.py", line 150, in loadEthMensaForParams
    curr_mensa.category("ETH-Zentrum")
TypeError: 'str' object is not callable

2019-07-29 10:00:20 [ERROR   ] [flask_app.server.main:204           ] object of type 'NoneType' has no len()
2019-07-29 10:00:20 [ERROR   ] [flask_app.server.main:205           ] Traceback (most recent call last):
  File "C:\Users\renez\OneDrive\Dokumente\zhmensa\backend\flask_app\server.py", line 198, in main
    loadEthMensa(startOfWeek)
  File "C:\Users\renez\OneDrive\Dokumente\zhmensa\backend\flask_app\server.py", line 162, in loadEthMensa
    loadEthMensaForParams("de", str(startOfWeek + timedelta(days = i)), "lunch", i)
  File "C:\Users\renez\OneDrive\Dokumente\zhmensa\backend\flask_app\server.py", line 149, in loadEthMensaForParams
    mealType = MealType(mensa, type)
  File "C:\Users\renez\OneDrive\Dokumente\zhmensa\backend\flask_app\server.py", line 240, in __init__
    self.menus.append(Menu(menu, jsonObject["mensa"]))
  File "C:\Users\renez\OneDrive\Dokumente\zhmensa\backend\flask_app\server.py", line 247, in __init__
    self.prices = self.convertPricesToStr( meal["prices"])
  File "C:\Users\renez\OneDrive\Dokumente\zhmensa\backend\flask_app\server.py", line 261, in convertPricesToStr
    if(len(string) == 0):
TypeError: object of type 'NoneType' has no len()

2019-07-30 18:27:24 [ERROR   ] [flask_app.server.main:204           ] 'allergenes'
2019-07-30 18:27:24 [ERROR   ] [flask_app.server.main:205           ] Traceback (most recent call last):
  File "C:\Users\renez\OneDrive\Dokumente\zhmensa\backend\flask_app\server.py", line 198, in main
    loadEthMensa(startOfWeek)
  File "C:\Users\renez\OneDrive\Dokumente\zhmensa\backend\flask_app\server.py", line 162, in loadEthMensa
    loadEthMensaForParams("de", str(startOfWeek + timedelta(days = i)), "lunch", i)
  File "C:\Users\renez\OneDrive\Dokumente\zhmensa\backend\flask_app\server.py", line 149, in loadEthMensaForParams
    mealType = MealType(mensa, type)
  File "C:\Users\renez\OneDrive\Dokumente\zhmensa\backend\flask_app\server.py", line 241, in __init__
    menuObj = Menu(menu, jsonObject["mensa"]);
  File "C:\Users\renez\OneDrive\Dokumente\zhmensa\backend\flask_app\server.py", line 266, in __init__
    self.allergene = self.convertAllergeneToStr(meal["allergenes"]);
KeyError: 'allergenes'

2019-07-30 18:28:02 [ERROR   ] [flask_app.server.main:204           ] list indices must be integers or slices, not dict
2019-07-30 18:28:02 [ERROR   ] [flask_app.server.main:205           ] Traceback (most recent call last):
  File "C:\Users\renez\OneDrive\Dokumente\zhmensa\backend\flask_app\server.py", line 198, in main
    loadEthMensa(startOfWeek)
  File "C:\Users\renez\OneDrive\Dokumente\zhmensa\backend\flask_app\server.py", line 162, in loadEthMensa
    loadEthMensaForParams("de", str(startOfWeek + timedelta(days = i)), "lunch", i)
  File "C:\Users\renez\OneDrive\Dokumente\zhmensa\backend\flask_app\server.py", line 149, in loadEthMensaForParams
    mealType = MealType(mensa, type)
  File "C:\Users\renez\OneDrive\Dokumente\zhmensa\backend\flask_app\server.py", line 241, in __init__
    menuObj = Menu(menu, jsonObject["mensa"]);
  File "C:\Users\renez\OneDrive\Dokumente\zhmensa\backend\flask_app\server.py", line 266, in __init__
    self.allergene = self.convertAllergeneToStr(meal["allergens"]);
  File "C:\Users\renez\OneDrive\Dokumente\zhmensa\backend\flask_app\server.py", line 271, in convertAllergeneToStr
    line = jsonObj[tag]
TypeError: list indices must be integers or slices, not dict

2019-07-30 18:29:33 [ERROR   ] [flask_app.server.main:204           ] list indices must be integers or slices, not dict
2019-07-30 18:29:33 [ERROR   ] [flask_app.server.main:205           ] Traceback (most recent call last):
  File "C:\Users\renez\OneDrive\Dokumente\zhmensa\backend\flask_app\server.py", line 198, in main
    loadEthMensa(startOfWeek)
  File "C:\Users\renez\OneDrive\Dokumente\zhmensa\backend\flask_app\server.py", line 162, in loadEthMensa
    loadEthMensaForParams("de", str(startOfWeek + timedelta(days = i)), "lunch", i)
  File "C:\Users\renez\OneDrive\Dokumente\zhmensa\backend\flask_app\server.py", line 149, in loadEthMensaForParams
    mealType = MealType(mensa, type)
  File "C:\Users\renez\OneDrive\Dokumente\zhmensa\backend\flask_app\server.py", line 241, in __init__
    menuObj = Menu(menu, jsonObject["mensa"]);
  File "C:\Users\renez\OneDrive\Dokumente\zhmensa\backend\flask_app\server.py", line 266, in __init__
    self.allergene = self.convertAllergeneToStr(meal["allergens"]);
  File "C:\Users\renez\OneDrive\Dokumente\zhmensa\backend\flask_app\server.py", line 272, in convertAllergeneToStr
    line = jsonObj[tag]
TypeError: list indices must be integers or slices, not dict

2019-07-30 18:29:58 [ERROR   ] [flask_app.server.main:204           ] 1
2019-07-30 18:29:58 [ERROR   ] [flask_app.server.main:205           ] Traceback (most recent call last):
  File "C:\Users\renez\OneDrive\Dokumente\zhmensa\backend\flask_app\server.py", line 198, in main
    loadEthMensa(startOfWeek)
  File "C:\Users\renez\OneDrive\Dokumente\zhmensa\backend\flask_app\server.py", line 162, in loadEthMensa
    loadEthMensaForParams("de", str(startOfWeek + timedelta(days = i)), "lunch", i)
  File "C:\Users\renez\OneDrive\Dokumente\zhmensa\backend\flask_app\server.py", line 149, in loadEthMensaForParams
    mealType = MealType(mensa, type)
  File "C:\Users\renez\OneDrive\Dokumente\zhmensa\backend\flask_app\server.py", line 241, in __init__
    menuObj = Menu(menu, jsonObject["mensa"]);
  File "C:\Users\renez\OneDrive\Dokumente\zhmensa\backend\flask_app\server.py", line 266, in __init__
    self.allergene = self.convertAllergeneToStr(meal["allergens"]);
  File "C:\Users\renez\OneDrive\Dokumente\zhmensa\backend\flask_app\server.py", line 271, in convertAllergeneToStr
    list.append(tag[1])
KeyError: 1

2019-07-30 18:30:11 [ERROR   ] [flask_app.server.main:204           ] 1
2019-07-30 18:30:11 [ERROR   ] [flask_app.server.main:205           ] Traceback (most recent call last):
  File "C:\Users\renez\OneDrive\Dokumente\zhmensa\backend\flask_app\server.py", line 198, in main
    loadEthMensa(startOfWeek)
  File "C:\Users\renez\OneDrive\Dokumente\zhmensa\backend\flask_app\server.py", line 162, in loadEthMensa
    loadEthMensaForParams("de", str(startOfWeek + timedelta(days = i)), "lunch", i)
  File "C:\Users\renez\OneDrive\Dokumente\zhmensa\backend\flask_app\server.py", line 149, in loadEthMensaForParams
    mealType = MealType(mensa, type)
  File "C:\Users\renez\OneDrive\Dokumente\zhmensa\backend\flask_app\server.py", line 241, in __init__
    menuObj = Menu(menu, jsonObject["mensa"]);
  File "C:\Users\renez\OneDrive\Dokumente\zhmensa\backend\flask_app\server.py", line 266, in __init__
    self.allergene = self.convertAllergeneToStr(meal["allergens"]);
  File "C:\Users\renez\OneDrive\Dokumente\zhmensa\backend\flask_app\server.py", line 272, in convertAllergeneToStr
    list.append(tag[1])
KeyError: 1

2019-08-02 18:40:54 [ERROR   ] [flask_app.server.main:204           ] HTTPSConnectionPool(host='www.webservices.ethz.ch', port=443): Max retries exceeded with url: /gastro/v1/RVRI/Q1E1/meals/de/2019-07-29/lunch (Caused by NewConnectionError('<urllib3.connection.VerifiedHTTPSConnection object at 0x000002A427DF6390>: Failed to establish a new connection: [Errno 11001] getaddrinfo failed'))
2019-08-02 18:40:54 [ERROR   ] [flask_app.server.main:205           ] Traceback (most recent call last):
  File "C:\Users\renez\AppData\Local\Programs\Python\Python37\lib\site-packages\urllib3\connection.py", line 159, in _new_conn
    (self._dns_host, self.port), self.timeout, **extra_kw)
  File "C:\Users\renez\AppData\Local\Programs\Python\Python37\lib\site-packages\urllib3\util\connection.py", line 57, in create_connection
    for res in socket.getaddrinfo(host, port, family, socket.SOCK_STREAM):
  File "C:\Users\renez\AppData\Local\Programs\Python\Python37\lib\socket.py", line 748, in getaddrinfo
    for res in _socket.getaddrinfo(host, port, family, type, proto, flags):
socket.gaierror: [Errno 11001] getaddrinfo failed

During handling of the above exception, another exception occurred:

Traceback (most recent call last):
  File "C:\Users\renez\AppData\Local\Programs\Python\Python37\lib\site-packages\urllib3\connectionpool.py", line 600, in urlopen
    chunked=chunked)
  File "C:\Users\renez\AppData\Local\Programs\Python\Python37\lib\site-packages\urllib3\connectionpool.py", line 343, in _make_request
    self._validate_conn(conn)
  File "C:\Users\renez\AppData\Local\Programs\Python\Python37\lib\site-packages\urllib3\connectionpool.py", line 839, in _validate_conn
    conn.connect()
  File "C:\Users\renez\AppData\Local\Programs\Python\Python37\lib\site-packages\urllib3\connection.py", line 301, in connect
    conn = self._new_conn()
  File "C:\Users\renez\AppData\Local\Programs\Python\Python37\lib\site-packages\urllib3\connection.py", line 168, in _new_conn
    self, "Failed to establish a new connection: %s" % e)
urllib3.exceptions.NewConnectionError: <urllib3.connection.VerifiedHTTPSConnection object at 0x000002A427DF6390>: Failed to establish a new connection: [Errno 11001] getaddrinfo failed

During handling of the above exception, another exception occurred:

Traceback (most recent call last):
  File "C:\Users\renez\AppData\Local\Programs\Python\Python37\lib\site-packages\requests\adapters.py", line 449, in send
    timeout=timeout
  File "C:\Users\renez\AppData\Local\Programs\Python\Python37\lib\site-packages\urllib3\connectionpool.py", line 638, in urlopen
    _stacktrace=sys.exc_info()[2])
  File "C:\Users\renez\AppData\Local\Programs\Python\Python37\lib\site-packages\urllib3\util\retry.py", line 398, in increment
    raise MaxRetryError(_pool, url, error or ResponseError(cause))
urllib3.exceptions.MaxRetryError: HTTPSConnectionPool(host='www.webservices.ethz.ch', port=443): Max retries exceeded with url: /gastro/v1/RVRI/Q1E1/meals/de/2019-07-29/lunch (Caused by NewConnectionError('<urllib3.connection.VerifiedHTTPSConnection object at 0x000002A427DF6390>: Failed to establish a new connection: [Errno 11001] getaddrinfo failed'))

During handling of the above exception, another exception occurred:

Traceback (most recent call last):
  File "C:\Users\renez\OneDrive\Dokumente\zhmensa\backend\flask_app\server.py", line 198, in main
    loadEthMensa(startOfWeek)
  File "C:\Users\renez\OneDrive\Dokumente\zhmensa\backend\flask_app\server.py", line 162, in loadEthMensa
    loadEthMensaForParams("de", str(startOfWeek + timedelta(days = i)), "lunch", i)
  File "C:\Users\renez\OneDrive\Dokumente\zhmensa\backend\flask_app\server.py", line 136, in loadEthMensaForParams
    r = requests.get(url = URL)
  File "C:\Users\renez\AppData\Local\Programs\Python\Python37\lib\site-packages\requests\api.py", line 75, in get
    return request('get', url, params=params, **kwargs)
  File "C:\Users\renez\AppData\Local\Programs\Python\Python37\lib\site-packages\requests\api.py", line 60, in request
    return session.request(method=method, url=url, **kwargs)
  File "C:\Users\renez\AppData\Local\Programs\Python\Python37\lib\site-packages\requests\sessions.py", line 533, in request
    resp = self.send(prep, **send_kwargs)
  File "C:\Users\renez\AppData\Local\Programs\Python\Python37\lib\site-packages\requests\sessions.py", line 646, in send
    r = adapter.send(request, **kwargs)
  File "C:\Users\renez\AppData\Local\Programs\Python\Python37\lib\site-packages\requests\adapters.py", line 516, in send
    raise ConnectionError(e, request=request)
requests.exceptions.ConnectionError: HTTPSConnectionPool(host='www.webservices.ethz.ch', port=443): Max retries exceeded with url: /gastro/v1/RVRI/Q1E1/meals/de/2019-07-29/lunch (Caused by NewConnectionError('<urllib3.connection.VerifiedHTTPSConnection object at 0x000002A427DF6390>: Failed to establish a new connection: [Errno 11001] getaddrinfo failed'))

2019-08-04 12:42:39 [ERROR   ] [flask_app.server.main:211           ] name 'ETHMenu' is not defined
2019-08-04 12:42:39 [ERROR   ] [flask_app.server.main:212           ] Traceback (most recent call last):
  File "C:\Users\renez\OneDrive\Dokumente\zhmensa\backend\flask_app\server.py", line 205, in main
    loadEthMensa(startOfWeek)
  File "C:\Users\renez\OneDrive\Dokumente\zhmensa\backend\flask_app\server.py", line 336, in loadEthMensa
    loadEthMensaForParams("de", str(startOfWeek + timedelta(days = i)), "lunch", i)
  File "C:\Users\renez\OneDrive\Dokumente\zhmensa\backend\flask_app\server.py", line 323, in loadEthMensaForParams
    mealType = ETHMealType(mensa, type)
  File "C:\Users\renez\OneDrive\Dokumente\zhmensa\backend\flask_app\server.py", line 392, in __init__
    menuObj = ETHMenu(menu, jsonObject["mensa"]);
NameError: name 'ETHMenu' is not defined

